<?xml version="1.0" encoding="utf-8"?>
<!-- This URDF was automatically created by SolidWorks to URDF Exporter! Originally created by Stephen Brawner (brawner@gmail.com) 
     Commit Version: 1.6.0-1-g15f4949  Build Version: 1.6.7594.29634
     For more information, please see http://wiki.ros.org/sw_urdf_exporter -->
<robot
  name="mini2_description">
<!-- Used for fixing robot to Gazebo 'body_link' -->
  <link name="world"/>
  <link name="odom"/>

  <joint name="world_to_odom" type="fixed">
    <origin
      xyz="0 0 0.1"
      rpy="0 0 0" />
    <parent link="world"/>
    <child link="odom"/>
  </joint>

  <joint name="odom_to_base_link" type="fixed">
    <parent link="odom"/>
    <child link="base_link"/>
  </joint>

  <!-- <joint name="world_fixed" type="fixed">
    <origin
      xyz="0 0 0.1"
      rpy="0 0 0" />
    <parent link="world"/>
    <child link="base_link"/>
  </joint> -->

  <link
    name="base_link">
    <inertial>
      <origin
        xyz="0.0244236973111199 -1.18543479083258E-05 0.00216186909321295"
        rpy="0 0 0" />
      <mass
        value="0.0903638663486848" />
      <inertia
        ixx="3.1165717171415E-05"
        ixy="5.90406353084212E-08"
        ixz="3.10782912189539E-07"
        iyy="0.000106657880847992"
        iyz="2.39226598820896E-09"
        izz="0.000122402395534927" />
    </inertial>
    <visual>
      <origin
        xyz="0 0 0"
        rpy="0 0 0" />
      <geometry>
        <mesh
          filename="package://mini2_description/meshes/base_link.STL" />
      </geometry>
      <material
        name="">
        <color
          rgba="1 1 1 1" />
      </material>
    </visual>
    <collision>
      <origin
        xyz="0 0 0"
        rpy="0 0 0" />
      <geometry>
        <mesh
          filename="package://mini2_description/meshes/base_link.STL" />
      </geometry>
    </collision>
  </link>
  <link
    name="13_Link">
    <inertial>
      <origin
        xyz="0.0248280194388737 0.00902150780643676 0.00422313927973027"
        rpy="0 0 0" />
      <mass
        value="0.00753841426198611" />
      <inertia
        ixx="1.41466984431918E-06"
        ixy="-4.34670034449555E-07"
        ixz="-2.11581372888087E-07"
        iyy="2.57074817290843E-06"
        iyz="-9.80909593732643E-08"
        izz="2.19885431130067E-06" />
    </inertial>
    <visual>
      <origin
        xyz="0 0 0"
        rpy="0 0 0" />
      <geometry>
        <mesh
          filename="package://mini2_description/meshes/13_Link.STL" />
      </geometry>
      <material
        name="">
        <color
          rgba="1 1 1 1" />
      </material>
    </visual>
    <collision>
      <origin
        xyz="0 0 0"
        rpy="0 0 0" />
      <geometry>
        <mesh
          filename="package://mini2_description/meshes/13_Link.STL" />
      </geometry>
    </collision>
  </link>
  <joint
    name="13_Joint"
    type="continuous">
    <origin
      xyz="0.075 0.0225 0"
      rpy="1.5708 0 1.5708" />
    <parent
      link="base_link" />
    <child
      link="13_Link" />
    <axis
      xyz="0 0  1" />
  </joint>
  <link
    name="12_Link">
    <inertial>
      <origin
        xyz="0.0299500382842132 0.00278863986388048 0.000781254345677947"
        rpy="0 0 0" />
      <mass
        value="0.0113861104442955" />
      <inertia
        ixx="8.8274846767819E-07"
        ixy="1.70456968614513E-11"
        ixz="-5.54531137474986E-13"
        iyy="2.37552837358265E-06"
        iyz="2.17118765723791E-15"
        izz="2.23822862488442E-06" />
    </inertial>
    <visual>
      <origin
        xyz="0 0 0"
        rpy="0 0 0" />
      <geometry>
        <mesh
          filename="package://mini2_description/meshes/12_Link.STL" />
      </geometry>
      <material
        name="">
        <color
          rgba="1 1 1 1" />
      </material>
    </visual>
    <collision>
      <origin
        xyz="0 0 0"
        rpy="0 0 0" />
      <geometry>
        <mesh
          filename="package://mini2_description/meshes/12_Link.STL" />
      </geometry>
    </collision>
  </link>
  <joint
    name="12_Joint"
    type="continuous">
    <origin
      xyz="0.030988 0 0"
      rpy="-1.5708 0 -1.5708" />
    <parent
      link="13_Link" />
    <child
      link="12_Link" />
    <axis
      xyz="0 0  1" />
  </joint>
  <link
    name="11_Link">
    <inertial>
      <origin
        xyz="0.00664275467176662 -0.0381915924275808 -1.35558841929395E-09"
        rpy="0 0 0" />
      <mass
        value="0.0153098671259445" />
      <inertia
        ixx="7.28173977633567E-06"
        ixy="-1.72792899462682E-06"
        ixz="-4.63227423006185E-13"
        iyy="1.09060089074474E-06"
        iyz="-3.27598612704548E-13"
        izz="7.54879294562872E-06" />
    </inertial>
    <visual>
      <origin
        xyz="0 0 0"
        rpy="0 0 0" />
      <geometry>
        <mesh
          filename="package://mini2_description/meshes/11_Link.STL" />
      </geometry>
      <material
        name="">
        <color
          rgba="1 1 1 1" />
      </material>
    </visual>
    <collision>
      <origin
        xyz="0 0 0"
        rpy="0 0 0" />
      <geometry>
        <mesh
          filename="package://mini2_description/meshes/11_Link.STL" />
      </geometry>
    </collision>
  </link>
  <joint
    name="11_Joint"
    type="continuous">
    <origin
      xyz="0.0599 0 0"
      rpy="0 0 0" />
    <parent
      link="12_Link" />
    <child
      link="11_Link" />
    <axis
      xyz="0 0  1" />
  </joint>
  <link
    name="10_Link">
    <inertial>
      <origin
        xyz="0.000424477269554246 -1.81550998540336E-09 0.000743181675761886"
        rpy="0 0 0" />
      <mass
        value="0.0625" />
      <inertia
        ixx="3.88852646564769E-08"
        ixy="3.60583012427767E-14"
        ixz="-2.99983098577409E-09"
        iyy="5.81684749230997E-08"
        iyz="1.31966996419541E-14"
        izz="2.7893076025217E-08" />
    </inertial>
    <visual>
      <origin
        xyz="0 0 0"
        rpy="0 0 0" />
      <geometry>
        <mesh
          filename="package://mini2_description/meshes/lffoot.STL" />
      </geometry>
      <material
        name="">
        <color
          rgba="0.2 0.2 0.2 1" />
      </material>
    </visual>
    <collision>
      <origin
        xyz="0 0 0"
        rpy="0 0 0" />
      <geometry>
        <mesh
          filename="package://mini2_description/meshes/lffoot.STL" />
      </geometry>
    </collision>
  </link>
  <joint
    name="10_Joint"
    type="fixed">
    <origin
      xyz="0.001 -0.0759880541805861 0"
      rpy="-1.57079632679488 0 0" />
    <parent
      link="11_Link" />
    <child
      link="10_Link" />
    <axis
      xyz="0 0 0" />
  </joint>
  <link
    name="23_Link">
    <inertial>
      <origin
        xyz="-0.00902149882128787 -0.0248280149220554 0.00422313254240891"
        rpy="0 0 0" />
      <mass
        value="0.00753841291835744" />
      <inertia
        ixx="2.57074897217913E-06"
        ixy="-4.34670427001712E-07"
        ixz="9.80904660290261E-08"
        iyy="1.41466883651307E-06"
        iyz="2.1158163905561E-07"
        izz="2.19885444494647E-06" />
    </inertial>
    <visual>
      <origin
        xyz="0 0 0"
        rpy="0 0 0" />
      <geometry>
        <mesh
          filename="package://mini2_description/meshes/23_Link.STL" />
      </geometry>
      <material
        name="">
        <color
          rgba="1 1 1 1" />
      </material>
    </visual>
    <collision>
      <origin
        xyz="0 0 0"
        rpy="0 0 0" />
      <geometry>
        <mesh
          filename="package://mini2_description/meshes/23_Link.STL" />
      </geometry>
    </collision>
  </link>
  <joint
    name="23_Joint"
    type="continuous">
    <origin
      xyz="0.075 -0.0225000398533523 0"
      rpy="0 1.5707963267949 0" />
    <parent
      link="base_link" />
    <child
      link="23_Link" />
    <axis
      xyz="0 0  1" />
  </joint>
  <link
    name="22_Link">
    <inertial>
      <origin
        xyz="0.0299500195755494 0.00278865061118515 -0.000781232629103762"
        rpy="0 0 0" />
      <mass
        value="0.0113861476387173" />
      <inertia
        ixx="8.82741917396447E-07"
        ixy="2.2691552768709E-11"
        ixz="-4.90122018356969E-13"
        iyy="2.37552727000979E-06"
        iyz="5.55387173553793E-15"
        izz="2.23823235437804E-06" />
    </inertial>
    <visual>
      <origin
        xyz="0 0 0"
        rpy="0 0 0" />
      <geometry>
        <mesh
          filename="package://mini2_description/meshes/22_Link.STL" />
      </geometry>
      <material
        name="">
        <color
          rgba="1 1 1 1" />
      </material>
    </visual>
    <collision>
      <origin
        xyz="0 0 0"
        rpy="0 0 0" />
      <geometry>
        <mesh
          filename="package://mini2_description/meshes/22_Link.STL" />
      </geometry>
    </collision>
  </link>
  <joint
    name="22_Joint"
    type="continuous">
    <origin
      xyz="0 -0.0309880541805861 0"
      rpy="-1.57079632679488 0 0" />
    <parent
      link="23_Link" />
    <child
      link="22_Link" />
    <axis
      xyz="0 0  1" />
  </joint>
  <link
    name="21_Link">
    <inertial>
      <origin
        xyz="0.00664275942926147 -0.0381915727668842 -1.39671030158217E-08"
        rpy="0 0 0" />
      <mass
        value="0.0153098502146296" />
      <inertia
        ixx="7.28173660879263E-06"
        ixy="-1.72792711230226E-06"
        ixz="-8.97883517326497E-13"
        iyy="1.09060159443016E-06"
        iyz="-4.59761514938139E-12"
        izz="7.54879088872956E-06" />
    </inertial>
    <visual>
      <origin
        xyz="0 0 0"
        rpy="0 0 0" />
      <geometry>
        <mesh
          filename="package://mini2_description/meshes/21_Link.STL" />
      </geometry>
      <material
        name="">
        <color
          rgba="1 1 1 1" />
      </material>
    </visual>
    <collision>
      <origin
        xyz="0 0 0"
        rpy="0 0 0" />
      <geometry>
        <mesh
          filename="package://mini2_description/meshes/21_Link.STL" />
      </geometry>
    </collision>
  </link>
  <joint
    name="21_Joint"
    type="continuous">
    <origin
      xyz="0.0599000797066995 0 0"
      rpy="0 0 0" />
    <parent
      link="22_Link" />
    <child
      link="21_Link" />
    <axis
      xyz="0 0  1" />
  </joint>
  <link
    name="20_Link">
    <inertial>
      <origin
        xyz="0.000424477269554566 4.99981844905087E-05 0.000743181675762233"
        rpy="0 0 0" />
      <mass
        value="0.0625" />
      <inertia
        ixx="3.88852646564774E-08"
        ixy="3.60583012797131E-14"
        ixz="-2.99983098577438E-09"
        iyy="5.81684749231005E-08"
        iyz="1.31966996988911E-14"
        izz="2.78930760252171E-08" />
    </inertial>
    <visual>
      <origin
        xyz="0 0 0"
        rpy="0 0 0" />
      <geometry>
        <mesh
          filename="package://mini2_description/meshes/rffoot.STL" />
      </geometry>
      <material
        name="">
        <color
          rgba="0.2 0.2 0.2 1" />
      </material>
    </visual>
    <collision>
      <origin
        xyz="0 0 0"
        rpy="0 0 0" />
      <geometry>
        <mesh
          filename="package://mini2_description/meshes/rffoot.STL" />
      </geometry>
    </collision>
  </link>
  <joint
    name="20_Joint"
    type="fixed">
    <origin
      xyz="0.001 -0.0759880541805861 0"
      rpy="-1.57079632679488 0 0" />
    <parent
      link="21_Link" />
    <child
      link="20_Link" />
    <axis
      xyz="0 0 0" />
  </joint>
  <link
    name="33_Link">
    <inertial>
      <origin
        xyz="-0.00902149882128814 -0.0248280149220534 0.00422313254241374"
        rpy="0 0 0" />
      <mass
        value="0.00753841291835745" />
      <inertia
        ixx="2.57074897217914E-06"
        ixy="-4.34670427001711E-07"
        ixz="9.80904660290273E-08"
        iyy="1.41466883651307E-06"
        iyz="2.11581639055611E-07"
        izz="2.19885444494647E-06" />
    </inertial>
    <visual>
      <origin
        xyz="0 0 0"
        rpy="0 0 0" />
      <geometry>
        <mesh
          filename="package://mini2_description/meshes/33_Link.STL" />
      </geometry>
      <material
        name="">
        <color
          rgba="1 1 1 1" />
      </material>
    </visual>
    <collision>
      <origin
        xyz="0 0 0"
        rpy="0 0 0" />
      <geometry>
        <mesh
          filename="package://mini2_description/meshes/33_Link.STL" />
      </geometry>
    </collision>
  </link>
  <joint
    name="33_Joint"
    type="continuous">
    <origin
      xyz="-0.075 -0.0225000398533512 0"
      rpy="0 1.5707963267949 0" />
    <parent
      link="base_link" />
    <child
      link="33_Link" />
    <axis
      xyz="0 0  1" />
  </joint>
  <link
    name="32_Link">
    <inertial>
      <origin
        xyz="0.0299500359079056 0.00278865255150929 -0.000781238975794393"
        rpy="0 0 0" />
      <mass
        value="0.0113861392484884" />
      <inertia
        ixx="8.82741864071183E-07"
        ixy="2.26994650204806E-11"
        ixz="-5.36563810036175E-13"
        iyy="2.37552718141011E-06"
        iyz="1.08306138546267E-15"
        izz="2.23823228203629E-06" />
    </inertial>
    <visual>
      <origin
        xyz="0 0 0"
        rpy="0 0 0" />
      <geometry>
        <mesh
          filename="package://mini2_description/meshes/32_Link.STL" />
      </geometry>
      <material
        name="">
        <color
          rgba="1 1 1 1" />
      </material>
    </visual>
    <collision>
      <origin
        xyz="0 0 0"
        rpy="0 0 0" />
      <geometry>
        <mesh
          filename="package://mini2_description/meshes/32_Link.STL" />
      </geometry>
    </collision>
  </link>
  <joint
    name="32_Joint"
    type="continuous">
    <origin
      xyz="0 -0.0309880541805845 0"
      rpy="-1.57079632679488 0 0" />
    <parent
      link="33_Link" />
    <child
      link="32_Link" />
    <axis
      xyz="0 0  1" />
  </joint>
  <link
    name="31_Link">
    <inertial>
      <origin
        xyz="0.00664275942886895 -0.0381915727801102 -1.39647855362801E-08"
        rpy="0 0 0" />
      <mass
        value="0.0153098502269143" />
      <inertia
        ixx="7.28173661196616E-06"
        ixy="-1.72792711238622E-06"
        ixz="-8.97900888843362E-13"
        iyy="1.09060159455208E-06"
        iyz="-4.59704907889622E-12"
        izz="7.54879089188839E-06" />
    </inertial>
    <visual>
      <origin
        xyz="0 0 0"
        rpy="0 0 0" />
      <geometry>
        <mesh
          filename="package://mini2_description/meshes/31_Link.STL" />
      </geometry>
      <material
        name="">
        <color
          rgba="1 1 1 1" />
      </material>
    </visual>
    <collision>
      <origin
        xyz="0 0 0"
        rpy="0 0 0" />
      <geometry>
        <mesh
          filename="package://mini2_description/meshes/31_Link.STL" />
      </geometry>
    </collision>
  </link>
  <joint
    name="31_Joint"
    type="continuous">
    <origin
      xyz="0.0599000797066995 0 0"
      rpy="0 0 0" />
    <parent
      link="32_Link" />
    <child
      link="31_Link" />
    <axis
      xyz="0 0  1" />
  </joint>
  <link name="30_Link">
    <inertial>
      <origin rpy="0 0 0" xyz="0.000424477269553421 4.99981844908973E-05 0.000743181675762136"/>
      <mass value="0.0625"/>
      <inertia ixx="3.88852646564768E-08" ixy="3.60583012702203E-14" ixz="-2.99983098577417E-09" iyy="5.81684749230997E-08" iyz="1.31966997511807E-14" izz="2.78930760252171E-08"/>
    </inertial>
    <visual>
      <origin rpy="0 0 0" xyz="0 0 0"/>
      <geometry>
        <mesh filename="package://mini_pupper_description/meshes/rbfoot.STL"/>
      </geometry>
      <material name="">
        <color rgba="0.2 0.2 0.2 1"/>
      </material>
    </visual>
    <collision>
      <origin rpy="0 0 0" xyz="0 0 0"/>
      <geometry>
        <mesh filename="package://mini_pupper_description/meshes/rbfoot.STL"/>
      </geometry>
    </collision>
  </link>
  <joint name="30_Joint" type="fixed">
    <origin rpy="-1.57079632679488 0 0" xyz="0.001 -0.0759880541805861 0"/>
    <parent link="31_Link"/>
    <child link="30_Link"/>
    <axis xyz="0 0 0"/>
  </joint>
  <link
    name="43_Link">
    <inertial>
      <origin
        xyz="-0.00902150780643703 0.0248280194388716 0.00422313927973639"
        rpy="0 0 0" />
      <mass
        value="0.00753841426198606" />
      <inertia
        ixx="2.57074817290842E-06"
        ixy="4.34670034449559E-07"
        ixz="9.80909593732633E-08"
        iyy="1.41466984431917E-06"
        iyz="-2.11581372888085E-07"
        izz="2.19885431130066E-06" />
    </inertial>
    <visual>
      <origin
        xyz="0 0 0"
        rpy="0 0 0" />
      <geometry>
        <mesh
          filename="package://mini2_description/meshes/43_Link.STL" />
      </geometry>
      <material
        name="">
        <color
          rgba="1 1 1 1" />
      </material>
    </visual>
    <collision>
      <origin
        xyz="0 0 0"
        rpy="0 0 0" />
      <geometry>
        <mesh
          filename="package://mini2_description/meshes/43_Link.STL" />
      </geometry>
    </collision>
  </link>
  <joint
    name="43_Joint"
    type="continuous">
    <origin
      xyz="-0.075 0.0225000398533488 0"
      rpy="0 1.5707963267949 0" />
    <parent
      link="base_link" />
    <child
      link="43_Link" />
    <axis
      xyz="0 0  1" />
  </joint>
  <link
    name="42_Link">
    <inertial>
      <origin
        xyz="0.0299500438125054 0.00278863921174038 0.000781256348017623"
        rpy="0 0 0" />
      <mass
        value="0.0113861123425769" />
      <inertia
        ixx="8.82748501091515E-07"
        ixy="1.69846167849517E-11"
        ixz="-5.16154756727328E-13"
        iyy="2.37552845343969E-06"
        iyz="7.26530034557828E-16"
        izz="2.23822873857817E-06" />
    </inertial>
    <visual>
      <origin
        xyz="0 0 0"
        rpy="0 0 0" />
      <geometry>
        <mesh
          filename="package://mini2_description/meshes/42_Link.STL" />
      </geometry>
      <material
        name="">
        <color
          rgba="1 1 1 1" />
      </material>
    </visual>
    <collision>
      <origin
        xyz="0 0 0"
        rpy="0 0 0" />
      <geometry>
        <mesh
          filename="package://mini2_description/meshes/42_Link.STL" />
      </geometry>
    </collision>
  </link>
  <joint
    name="42_Joint"
    type="continuous">
    <origin
      xyz="0 0.03098805418059 0"
      rpy="-1.57079632679488 0 0" />
    <parent
      link="43_Link" />
    <child
      link="42_Link" />
    <axis
      xyz="0 0  1" />
  </joint>
  <link
    name="41_Link">
    <inertial>
      <origin
        xyz="0.00664275467193516 -0.0381915928444575 -1.28866987914034E-09"
        rpy="0 0 0" />
      <mass
        value="0.0153098673781372" />
      <inertia
        ixx="7.28173993438346E-06"
        ixy="-1.72792899593328E-06"
        ixz="-4.629564354771E-13"
        iyy="1.09060089512517E-06"
        iyz="-3.01324069572266E-13"
        izz="7.54879309900224E-06" />
    </inertial>
    <visual>
      <origin
        xyz="0 0 0"
        rpy="0 0 0" />
      <geometry>
        <mesh
          filename="package://mini2_description/meshes/41_Link.STL" />
      </geometry>
      <material
        name="">
        <color
          rgba="1 1 1 1" />
      </material>
    </visual>
    <collision>
      <origin
        xyz="0 0 0"
        rpy="0 0 0" />
      <geometry>
        <mesh
          filename="package://mini2_description/meshes/41_Link.STL" />
      </geometry>
    </collision>
  </link>
  <joint
    name="41_Joint"
    type="continuous">
    <origin
      xyz="0.0599000797066993 0 0"
      rpy="0 0 0" />
    <parent
      link="42_Link" />
    <child
      link="41_Link" />
    <axis
      xyz="0 0  1" />
  </joint>
  <link name="40_Link">
    <inertial>
      <origin rpy="0 0 0" xyz="0.000424477269554052 -5.00018155106391E-05 0.000743181675762469"/>
      <mass value="0.0625"/>
      <inertia ixx="3.8885264656477E-08" ixy="3.60583012801976E-14" ixz="-2.99983098577426E-09" iyy="5.81684749230999E-08" iyz="1.31966997327651E-14" izz="2.7893076025217E-08"/>
    </inertial>
    <visual>
      <origin rpy="0 0 0" xyz="0 0 0"/>
      <geometry>
        <mesh filename="package://mini2_description/meshes/lbfoot.STL"/>
      </geometry>
      <material name="">
        <color rgba="0.2 0.2 0.2 1"/>
      </material>
    </visual>
    <collision>
      <origin rpy="0 0 0" xyz="0 0 0"/>
      <geometry>
        <mesh filename="package://mini2_description/meshes/lbfoot.STL"/>
      </geometry>
    </collision>
  </link>
  <joint name="40_Joint" type="fixed">
    <origin rpy="-1.57079632679488 0 0" xyz="0.001 -0.0759880541805861 0" />
    <parent link="41_Link"/>
    <child link="40_Link"/>
    <axis xyz="0 0 0"/>
  </joint>
  <link
    name="53_Link">
    <inertial>
      <origin
        xyz="-0.0299500408748984 0.00278863968474263 0.000756254106578605"
        rpy="0 0 0" />
      <mass
        value="0.0113861109184074" />
      <inertia
        ixx="8.8274847658028E-07"
        ixy="1.70465094959684E-11"
        ixz="-5.53980250412205E-13"
        iyy="2.37552837874193E-06"
        iyz="2.679275013287E-15"
        izz="2.23822863876479E-06" />
    </inertial>
    <visual>
      <origin
        xyz="0 0 0"
        rpy="3.1416 0 0" />
      <geometry>
        <mesh
          filename="package://mini2_description/meshes/53_Link.STL" />
      </geometry>
      <material
        name="">
        <color
          rgba="1 1 1 1" />
      </material>
    </visual>
    <collision>
      <origin
        xyz="0 0 0"
        rpy="0 0 0" />
      <geometry>
        <mesh
          filename="package://mini2_description/meshes/53_Link.STL" />
      </geometry>
    </collision>
  </link>
  <joint
    name="53_Joint"
    type="continuous">
    <origin
      xyz="0.0817510268642972 0 0.0378543330962328"
      rpy="1.57079632679488 1.5707963267949 0" />
    <parent
      link="base_link" />
    <child
      link="53_Link" />
    <axis
      xyz="0 0  1" />
  </joint>
  <link
    name="52_Link">
    <inertial>
      <origin
        xyz="-0.0187892739076206 -0.0338603318634318 -3.92639937411808E-05"
        rpy="0 0 0" />
      <mass
        value="0.0148330426207503" />
      <inertia
        ixx="3.01305231852195E-06"
        ixy="-2.65003761424246E-07"
        ixz="8.46914201667833E-12"
        iyy="1.09918857594476E-06"
        iyz="-4.9217583562805E-12"
        izz="3.06331536234519E-06" />
    </inertial>
    <visual>
      <origin
        xyz="0 0 0"
        rpy="0 0 0" />
      <geometry>
        <mesh
          filename="package://mini2_description/meshes/52_Link.STL" />
      </geometry>
      <material
        name="">
        <color
          rgba="1 1 1 1" />
      </material>
    </visual>
    <collision>
      <origin
        xyz="0 0 0"
        rpy="0 0 0" />
      <geometry>
        <mesh
          filename="package://mini2_description/meshes/52_Link.STL" />
      </geometry>
    </collision>
  </link>
  <joint
    name="52_Joint"
    type="continuous">
    <origin
      xyz="-0.0599000797066993 0 0"
      rpy="3.1416 0 0" />
    <parent
      link="53_Link" />
    <child
      link="52_Link" />
    <axis
      xyz="0 0  1" />
  </joint>
  <link
    name="51_Link">
    <inertial>
      <origin
        xyz="-1.16778674230655E-09 -2.04686758167871E-09 -0.00208665364177515"
        rpy="0 0 0" />
      <mass
        value="0.000719672080560025" />
      <inertia
        ixx="8.90538782569087E-09"
        ixy="-4.86887856334375E-13"
        ixz="5.07468190192859E-16"
        iyy="8.90502666587485E-09"
        iyz="6.11687760319459E-16"
        izz="1.59175104815061E-08" />
    </inertial>
    <visual>
      <origin
        xyz="0 0 0"
        rpy="0 0 0" />
      <geometry>
        <mesh
          filename="package://mini2_description/meshes/51_Link.STL" />
      </geometry>
      <material
        name="">
        <color
          rgba="1 1 1 1" />
      </material>
    </visual>
    <collision>
      <origin
        xyz="0 0 0"
        rpy="0 0 0" />
      <geometry>
        <mesh
          filename="package://mini2_description/meshes/51_Link.STL" />
      </geometry>
    </collision>
  </link>
  <joint
    name="51_Joint"
    type="continuous">
    <origin
      xyz="-0.018371 -0.0783 -2.5E-05"
      rpy="-1.5708 0 -3.1416" />
    <parent
      link="52_Link" />
    <child
      link="51_Link" />
    <axis
      xyz="0 0  1" />
  </joint>
  <link
    name="50_Link">
    <inertial>
      <origin
        xyz="-0.00459436196189859 0.00983058256711414 0.00450764373303642"
        rpy="0 0 0" />
      <mass
        value="0.00096518203674629" />
      <inertia
        ixx="2.28634282389431E-07"
        ixy="4.37714130906999E-08"
        ixz="3.29944701810298E-08"
        iyy="1.47678770055442E-07"
        iyz="-5.64255427630419E-08"
        izz="1.91146220698636E-07" />
    </inertial>
    <visual>
      <origin
        xyz="0 0 0"
        rpy="0 0 0" />
      <geometry>
        <mesh
          filename="package://mini2_description/meshes/50_Link.STL" />
      </geometry>
      <material
        name="">
        <color
          rgba="1 1 1 1" />
      </material>
    </visual>
    <collision>
      <origin
        xyz="0 0 0"
        rpy="0 0 0" />
      <geometry>
        <mesh
          filename="package://mini2_description/meshes/50_Link.STL" />
      </geometry>
    </collision>
  </link>
  <joint
    name="50_Joint"
    type="prismatic">
    <origin
      xyz="-0.018371 -0.096345 -0.018125"
      rpy="0 0 0" />
    <parent
      link="52_Link" />
    <child
      link="50_Link" />
    <axis
      xyz="0 0 1" />
    <limit
      lower="0"
      upper="0"
      effort="0"
      velocity="0" />
    <mimic
      joint="51_Joint"
      multiplier="0.072"
      offset="0" />
  </joint>
  <link
    name="500_Link">
    <inertial>
      <origin
        xyz="0.00459436196189864 0.00983058256711407 -0.0045076437330364"
        rpy="0 0 0" />
      <mass
        value="0.000965182036746288" />
      <inertia
        ixx="2.28634282389431E-07"
        ixy="-4.37714130906999E-08"
        ixz="3.299447018103E-08"
        iyy="1.47678770055441E-07"
        iyz="5.64255427630418E-08"
        izz="1.91146220698636E-07" />
    </inertial>
    <visual>
      <origin
        xyz="0 0 0"
        rpy="0 0 0" />
      <geometry>
        <mesh
          filename="package://mini2_description/meshes/500_Link.STL" />
      </geometry>
      <material
        name="">
        <color
          rgba="1 1 1 1" />
      </material>
    </visual>
    <collision>
      <origin
        xyz="0 0 0"
        rpy="0 0 0" />
      <geometry>
        <mesh
          filename="package://mini2_description/meshes/500_Link.STL" />
      </geometry>
    </collision>
  </link>
  <joint
    name="500_Joint"
    type="prismatic">
    <origin
      xyz="-0.018371 -0.096345 0.018075"
      rpy="0 0 0" />
    <parent
      link="52_Link" />
    <child
      link="500_Link" />
    <axis
      xyz="0 0 1" />
    <limit
      lower="0"
      upper="0"
      effort="0"
      velocity="0" />
    <mimic
      joint="51_Joint"
      multiplier="-0.072"
      offset="0" />
  </joint>
  <link name="lidar_link">
    <inertial>
      <origin rpy="0 0 1.5708" xyz="1.56706411611127E-05 -5.16565672073303E-13 -0.0191835739440227"/>
      <mass value="0.27"/>
      <inertia ixx="8.74731426973985E-06" ixy="-6.66781590704156E-08" ixz="1.89196685410159E-11" iyy="8.70097486591694E-06" iyz="-1.13397577799603E-17" izz="9.98821295317784E-06"/>
    </inertial>
    <visual>
      <origin rpy="0 0 1.5708" xyz="0 0 0"/>
      <geometry>
        <mesh filename="package://mini2_description/meshes/lidar.STL"/>
      </geometry>
      <material name="">
        <color rgba="0.2 0.2 0.2 1"/>
      </material>
    </visual>
    <collision>
      <origin rpy="0 0 1.5708" xyz="0 0 0"/>
      <geometry>
        <mesh filename="package://mini2_description/meshes/lidar.STL"/>
      </geometry>
    </collision>
  </link>
  <joint name="lidar_joint" type="fixed">
    <origin rpy="0 0 -1.5708" xyz="-0.070475 0.0001 0.055"/>
    <parent link="base_link"/>
    <child link="lidar_link"/>
    <axis xyz="0 0 0"/>
  </joint>
  <link name="imu_link">
    <inertial>
      <mass value="0.001"/>
      <origin rpy="0 0 0" xyz="0 0 0"/>
      <inertia ixx="1e-09" ixy="0.0" ixz="0.0" iyy="1e-09" iyz="0.0" izz="1e-09"/>
    </inertial>
  </link>
  <joint name="imu_joint" type="fixed">
    <parent link="base_link"/>
    <child link="imu_link"/>
  </joint>
</robot>
